I'm sorry, but an uncaught exception occurred.

While running game code:
  File "game/script.rpy", line 52, in script
    python:
  File "game/script.rpy", line 54, in <module>
    import ai
ModuleNotFoundError: No module named 'openai'

-- Full Traceback ------------------------------------------------------------

Full traceback:
  File "game/script.rpy", line 52, in script
    python:
  File "/Users/aya/Downloads/renpy-8.2.1-sdk/renpy/ast.py", line 823, in execute
    renpy.python.py_exec_bytecode(self.code.bytecode, self.hide, store=self.store)
  File "/Users/aya/Downloads/renpy-8.2.1-sdk/renpy/python.py", line 1178, in py_exec_bytecode
    exec(bytecode, globals, locals)
  File "game/script.rpy", line 54, in <module>
    import ai
  File "/Users/aya/Downloads/renpy-8.2.1-sdk/renpy/loader.py", line 876, in load_module
    exec(code, mod.__dict__) # type: ignore
  File "python-packages/ai/__init__.py", line 1, in <module>
ModuleNotFoundError: No module named 'openai'

macOS-10.16-x86_64-i386-64bit x86_64
Ren'Py 8.2.1.24030407
AIgnite the Mystery 1.0
Thu Mar  7 20:34:50 2024
